<sdf version='1.9'>
  <model name='slambot'>
    <link name='base_link'>
      <inertial>
        <pose>0.005119635718873044 -0.0001110159277754004 0.08162335600373799 0 0 0</pose>
        <mass>3.030592833049528</mass>
        <inertia>
          <ixx>0.013459</ixx>
          <ixy>5.0000000000000004e-06</ixy>
          <ixz>0.00077499999999999997</ixz>
          <iyy>0.014737</iyy>
          <iyz>-2.9e-05</iyz>
          <izz>0.0079419999999999994</izz>
        </inertia>
      </inertial>
      <collision name='base_link_collision'>
        <pose>0 0 0 0 0 0</pose>
        <geometry>
          <mesh>
            <scale>0.001 0.001 0.001</scale>
            <uri>model://tank_description/meshes/base_link.stl</uri>
          </mesh>
        </geometry>
        <surface>
          <contact>
            <ode/>
          </contact>
          <friction>
            <ode>
              <mu>0.20000000000000001</mu>
              <mu2>0.20000000000000001</mu2>
            </ode>
          </friction>
        </surface>
      </collision>
      <visual name='base_link_visual'>
        <pose>0 0 0 0 0 0</pose>
        <geometry>
          <mesh>
            <scale>0.001 0.001 0.001</scale>
            <uri>model://tank_description/meshes/base_link.stl</uri>
          </mesh>
        </geometry>
        <material>
          <script>
            <name>Gazebo/Silver</name>
            <uri>file://media/materials/scripts/gazebo.material</uri>
          </script>
          <diffuse>0.875 0.875 0.875 1</diffuse>
          <ambient>0.875 0.875 0.875 1</ambient>
        </material>
      </visual>
      <self_collide>true</self_collide>
      <gravity>true</gravity>
    </link>
    <joint name='revolution 3' type='revolute'>
      <pose relative_to='base_link'>0.000388 0.035625 0.018348 0 0 0</pose>
      <parent>base_link</parent>
      <child>Wheel2_1</child>
      <axis>
        <xyz>0 -1 0</xyz>
        <limit>
          <lower>-10000000000000000</lower>
          <upper>10000000000000000</upper>
        </limit>
        <dynamics>
          <spring_reference>0</spring_reference>
          <spring_stiffness>0</spring_stiffness>
        </dynamics>
      </axis>
    </joint>
    <link name='Wheel2_1'>
      <pose relative_to='revolution 3'>0 0 0 0 0 0</pose>
      <inertial>
        <pose>5.011070668196833e-05 0.01358677538118524 -3.30968138033752e-06 0 0 0</pose>
        <mass>0.41019155181649092</mass>
        <inertia>
          <ixx>0.00014200000000000001</ixx>
          <ixy>0</ixy>
          <ixz>0</ixz>
          <iyy>0.000242</iyy>
          <iyz>0</iyz>
          <izz>0.00014200000000000001</izz>
        </inertia>
      </inertial>
      <collision name='Wheel2_1_collision'>
        <pose>-0.000388 -0.035625 -0.018348 0 0 0</pose>
        <geometry>
          <mesh>
            <scale>0.001 0.001 0.001</scale>
            <uri>model://tank_description/meshes/Wheel2_1.stl</uri>
          </mesh>
        </geometry>
        <surface>
          <contact>
            <ode/>
          </contact>
          <friction>
            <ode>
              <mu>0.20000000000000001</mu>
              <mu2>0.20000000000000001</mu2>
            </ode>
          </friction>
        </surface>
      </collision>
      <visual name='Wheel2_1_visual'>
        <pose>-0.000388 -0.035625 -0.018348 0 0 0</pose>
        <geometry>
          <mesh>
            <scale>0.001 0.001 0.001</scale>
            <uri>model://tank_description/meshes/Wheel2_1.stl</uri>
          </mesh>
        </geometry>
        <material>
          <script>
            <name>Gazebo/Silver</name>
            <uri>file://media/materials/scripts/gazebo.material</uri>
          </script>
          <diffuse>0.875 0.875 0.875 1</diffuse>
          <ambient>0.875 0.875 0.875 1</ambient>
        </material>
      </visual>
      <self_collide>true</self_collide>
    </link>
    <joint name='revolution 5' type='revolute'>
      <pose relative_to='base_link'>0.000387 -0.036475 0.018348 0 0 0</pose>
      <parent>base_link</parent>
      <child>Wheel1_1</child>
      <axis>
        <xyz>0 -1 0</xyz>
        <limit>
          <lower>-10000000000000000</lower>
          <upper>10000000000000000</upper>
        </limit>
        <dynamics>
          <spring_reference>0</spring_reference>
          <spring_stiffness>0</spring_stiffness>
        </dynamics>
      </axis>
    </joint>
    <link name='Wheel1_1'>
      <pose relative_to='revolution 5'>0 0 0 0 0 0</pose>
      <inertial>
        <pose>3.573766185485487e-06 -0.01855466087531542 1.660531699224782e-05 0 0 0</pose>
        <mass>0.41151121249399281</mass>
        <inertia>
          <ixx>0.00014200000000000001</ixx>
          <ixy>0</ixy>
          <ixz>0</ixz>
          <iyy>0.000242</iyy>
          <iyz>0</iyz>
          <izz>0.00014200000000000001</izz>
        </inertia>
      </inertial>
      <collision name='Wheel1_1_collision'>
        <pose>-0.000387 0.036475 -0.018348 0 0 0</pose>
        <geometry>
          <mesh>
            <scale>0.001 0.001 0.001</scale>
            <uri>model://tank_description/meshes/Wheel1_1.stl</uri>
          </mesh>
        </geometry>
        <surface>
          <contact>
            <ode/>
          </contact>
          <friction>
            <ode>
              <mu>0.20000000000000001</mu>
              <mu2>0.20000000000000001</mu2>
            </ode>
          </friction>
        </surface>
      </collision>
      <visual name='Wheel1_1_visual'>
        <pose>-0.000387 0.036475 -0.018348 0 0 0</pose>
        <geometry>
          <mesh>
            <scale>0.001 0.001 0.001</scale>
            <uri>model://tank_description/meshes/Wheel1_1.stl</uri>
          </mesh>
        </geometry>
        <material>
          <script>
            <name>Gazebo/Silver</name>
            <uri>file://media/materials/scripts/gazebo.material</uri>
          </script>
          <diffuse>0.875 0.875 0.875 1</diffuse>
          <ambient>0.875 0.875 0.875 1</ambient>
        </material>
      </visual>
      <self_collide>true</self_collide>
    </link>
    <plugin name='control' filename='libgazebo_ros_control.so'/>
  </model>
</sdf>
